<?xml version="1.0" ?>
<robot name="Assembly_scaled" xmlns:xacro="http://www.ros.org/wiki/xacro">

<xacro:include filename="$(find Assembly_scaled_description)/urdf/materials.xacro" />
<xacro:include filename="$(find Assembly_scaled_description)/urdf/Assembly_scaled.trans" />
<xacro:include filename="$(find Assembly_scaled_description)/urdf/Assembly_scaled.gazebo" />
<link name="base_link v5">
  <inertial>
    <origin xyz="0.09000000134111852 0.01 -0.0420000008940697" rpy="0 0 0"/>
    <mass value="5.5241076800961295"/>
    <inertia ixx="0.018215" iyy="0.03263" izz="0.014783" ixy="0.0" iyz="-0.0" ixz="0.0"/>
  </inertial>
  <visual>
    <origin xyz="0 0 0" rpy="0 0 0"/>
    <geometry>
      <mesh filename="file://$(find Assembly_scaled_description)/meshes/base_link v5.stl" scale="0.001 0.001 0.001"/>
    </geometry>
    <material name="silver"/>
  </visual>
  <collision>
    <origin xyz="0 0 0" rpy="0 0 0"/>
    <geometry>
      <mesh filename="file://$(find Assembly_scaled_description)/meshes/base_link v5.stl" scale="0.001 0.001 0.001"/>
    </geometry>
  </collision>
</link>

<link name="wheel_f_v2_2">
  <inertial>
    <origin xyz="0.015000002682209024 1.0902737046514233e-14 0.0" rpy="0 0 0"/>
    <mass value="0.8878140839044747"/>
    <inertia ixx="0.000555" iyy="0.000344" izz="0.000344" ixy="0.0" iyz="0.0" ixz="0.0"/>
  </inertial>
  <visual>
    <origin xyz="-0.18 -0.01 0.08" rpy="0 0 0"/>
    <geometry>
      <mesh filename="file://$(find Assembly_scaled_description)/meshes/wheel_f_v2_2.stl" scale="0.001 0.001 0.001"/>
    </geometry>
    <material name="silver"/>
  </visual>
  <collision>
    <origin xyz="-0.18 -0.01 0.08" rpy="0 0 0"/>
    <geometry>
      <mesh filename="file://$(find Assembly_scaled_description)/meshes/wheel_f_v2_2.stl" scale="0.001 0.001 0.001"/>
    </geometry>
  </collision>
</link>

<link name="wheel_f_v2_1">
  <inertial>
    <origin xyz="0.015000002682209024 -1.0902737046514233e-14 -3.8576374173148304e-18" rpy="0 0 0"/>
    <mass value="0.8878140839044747"/>
    <inertia ixx="0.000555" iyy="0.000344" izz="0.000344" ixy="0.0" iyz="0.0" ixz="0.0"/>
  </inertial>
  <visual>
    <origin xyz="-0.18 -0.01 -0.0" rpy="0 0 0"/>
    <geometry>
      <mesh filename="file://$(find Assembly_scaled_description)/meshes/wheel_f_v2_1.stl" scale="0.001 0.001 0.001"/>
    </geometry>
    <material name="silver"/>
  </visual>
  <collision>
    <origin xyz="-0.18 -0.01 -0.0" rpy="0 0 0"/>
    <geometry>
      <mesh filename="file://$(find Assembly_scaled_description)/meshes/wheel_f_v2_1.stl" scale="0.001 0.001 0.001"/>
    </geometry>
  </collision>
</link>

<link name="wheel_f_v2_3">
  <inertial>
    <origin xyz="-0.015000000000000006 -1.0902737046514233e-14 -3.8576374173148304e-18" rpy="0 0 0"/>
    <mass value="0.8878140839044747"/>
    <inertia ixx="0.000555" iyy="0.000344" izz="0.000344" ixy="-0.0" iyz="0.0" ixz="0.0"/>
  </inertial>
  <visual>
    <origin xyz="-0.0 -0.01 -0.0" rpy="0 0 0"/>
    <geometry>
      <mesh filename="file://$(find Assembly_scaled_description)/meshes/wheel_f_v2_3.stl" scale="0.001 0.001 0.001"/>
    </geometry>
    <material name="silver"/>
  </visual>
  <collision>
    <origin xyz="-0.0 -0.01 -0.0" rpy="0 0 0"/>
    <geometry>
      <mesh filename="file://$(find Assembly_scaled_description)/meshes/wheel_f_v2_3.stl" scale="0.001 0.001 0.001"/>
    </geometry>
  </collision>
</link>

<link name="wheel_f_v2_4">
  <inertial>
    <origin xyz="-0.015000000000000006 -1.0902737046514233e-14 0.0" rpy="0 0 0"/>
    <mass value="0.8878140839044747"/>
    <inertia ixx="0.000555" iyy="0.000344" izz="0.000344" ixy="-0.0" iyz="0.0" ixz="0.0"/>
  </inertial>
  <visual>
    <origin xyz="-0.0 -0.01 0.08" rpy="0 0 0"/>
    <geometry>
      <mesh filename="file://$(find Assembly_scaled_description)/meshes/wheel_f_v2_4.stl" scale="0.001 0.001 0.001"/>
    </geometry>
    <material name="silver"/>
  </visual>
  <collision>
    <origin xyz="-0.0 -0.01 0.08" rpy="0 0 0"/>
    <geometry>
      <mesh filename="file://$(find Assembly_scaled_description)/meshes/wheel_f_v2_4.stl" scale="0.001 0.001 0.001"/>
    </geometry>
  </collision>
</link>

<link name="connector_v2_1">
  <inertial>
    <origin xyz="4.470348362317633e-10 -0.05000000000000001 -2.086162576020456e-09" rpy="0 0 0"/>
    <mass value="0.061653755826699685"/>
    <inertia ixx="5.2e-05" iyy="1e-06" izz="5.2e-05" ixy="0.0" iyz="-0.0" ixz="0.0"/>
  </inertial>
  <visual>
    <origin xyz="-0.03 -0.02 0.122" rpy="0 0 0"/>
    <geometry>
      <mesh filename="file://$(find Assembly_scaled_description)/meshes/connector_v2_1.stl" scale="0.001 0.001 0.001"/>
    </geometry>
    <material name="silver"/>
  </visual>
  <collision>
    <origin xyz="-0.03 -0.02 0.122" rpy="0 0 0"/>
    <geometry>
      <mesh filename="file://$(find Assembly_scaled_description)/meshes/connector_v2_1.stl" scale="0.001 0.001 0.001"/>
    </geometry>
  </collision>
</link>

<link name="connector_v2_2">
  <inertial>
    <origin xyz="2.2351741846282636e-09 -0.05000000000000001 -2.086162576020456e-09" rpy="0 0 0"/>
    <mass value="0.061653755826699685"/>
    <inertia ixx="5.2e-05" iyy="1e-06" izz="5.2e-05" ixy="0.0" iyz="-0.0" ixz="0.0"/>
  </inertial>
  <visual>
    <origin xyz="-0.15 -0.02 0.122" rpy="0 0 0"/>
    <geometry>
      <mesh filename="file://$(find Assembly_scaled_description)/meshes/connector_v2_2.stl" scale="0.001 0.001 0.001"/>
    </geometry>
    <material name="silver"/>
  </visual>
  <collision>
    <origin xyz="-0.15 -0.02 0.122" rpy="0 0 0"/>
    <geometry>
      <mesh filename="file://$(find Assembly_scaled_description)/meshes/connector_v2_2.stl" scale="0.001 0.001 0.001"/>
    </geometry>
  </collision>
</link>

<link name="connector_v2_3">
  <inertial>
    <origin xyz="4.470348362317633e-10 -0.05000000000000001 -8.940697002191023e-10" rpy="0 0 0"/>
    <mass value="0.061653755826699685"/>
    <inertia ixx="5.2e-05" iyy="1e-06" izz="5.2e-05" ixy="0.0" iyz="0.0" ixz="0.0"/>
  </inertial>
  <visual>
    <origin xyz="-0.03 -0.02 0.042" rpy="0 0 0"/>
    <geometry>
      <mesh filename="file://$(find Assembly_scaled_description)/meshes/connector_v2_3.stl" scale="0.001 0.001 0.001"/>
    </geometry>
    <material name="silver"/>
  </visual>
  <collision>
    <origin xyz="-0.03 -0.02 0.042" rpy="0 0 0"/>
    <geometry>
      <mesh filename="file://$(find Assembly_scaled_description)/meshes/connector_v2_3.stl" scale="0.001 0.001 0.001"/>
    </geometry>
  </collision>
</link>

<link name="connector_v2_4">
  <inertial>
    <origin xyz="2.2351741846282636e-09 -0.04999999999999999 -8.940697002191023e-10" rpy="0 0 0"/>
    <mass value="0.061653755826699685"/>
    <inertia ixx="5.2e-05" iyy="1e-06" izz="5.2e-05" ixy="0.0" iyz="0.0" ixz="0.0"/>
  </inertial>
  <visual>
    <origin xyz="-0.15 -0.02 0.042" rpy="0 0 0"/>
    <geometry>
      <mesh filename="file://$(find Assembly_scaled_description)/meshes/connector_v2_4.stl" scale="0.001 0.001 0.001"/>
    </geometry>
    <material name="silver"/>
  </visual>
  <collision>
    <origin xyz="-0.15 -0.02 0.042" rpy="0 0 0"/>
    <geometry>
      <mesh filename="file://$(find Assembly_scaled_description)/meshes/connector_v2_4.stl" scale="0.001 0.001 0.001"/>
    </geometry>
  </collision>
</link>

<link name="connector_v2_5">
  <inertial>
    <origin xyz="4.470348362317633e-10 -0.04999999999999999 2.9802319639893327e-10" rpy="0 0 0"/>
    <mass value="0.061653755826699685"/>
    <inertia ixx="5.2e-05" iyy="1e-06" izz="5.2e-05" ixy="-0.0" iyz="0.0" ixz="0.0"/>
  </inertial>
  <visual>
    <origin xyz="-0.03 -0.02 -0.038" rpy="0 0 0"/>
    <geometry>
      <mesh filename="file://$(find Assembly_scaled_description)/meshes/connector_v2_5.stl" scale="0.001 0.001 0.001"/>
    </geometry>
    <material name="silver"/>
  </visual>
  <collision>
    <origin xyz="-0.03 -0.02 -0.038" rpy="0 0 0"/>
    <geometry>
      <mesh filename="file://$(find Assembly_scaled_description)/meshes/connector_v2_5.stl" scale="0.001 0.001 0.001"/>
    </geometry>
  </collision>
</link>

<link name="connector_v2_6">
  <inertial>
    <origin xyz="2.2351741846282636e-09 -0.04999999999999999 2.9802319639893327e-10" rpy="0 0 0"/>
    <mass value="0.061653755826699685"/>
    <inertia ixx="5.2e-05" iyy="1e-06" izz="5.2e-05" ixy="0.0" iyz="0.0" ixz="0.0"/>
  </inertial>
  <visual>
    <origin xyz="-0.15 -0.02 -0.038" rpy="0 0 0"/>
    <geometry>
      <mesh filename="file://$(find Assembly_scaled_description)/meshes/connector_v2_6.stl" scale="0.001 0.001 0.001"/>
    </geometry>
    <material name="silver"/>
  </visual>
  <collision>
    <origin xyz="-0.15 -0.02 -0.038" rpy="0 0 0"/>
    <geometry>
      <mesh filename="file://$(find Assembly_scaled_description)/meshes/connector_v2_6.stl" scale="0.001 0.001 0.001"/>
    </geometry>
  </collision>
</link>

<link name="connector_v2_5">
  <inertial>
    <origin xyz="4.470348362317633e-10 0.05000000000000001 2.9802319639893327e-10" rpy="0 0 0"/>
    <mass value="0.061653755826699685"/>
    <inertia ixx="5.2e-05" iyy="1e-06" izz="5.2e-05" ixy="-0.0" iyz="0.0" ixz="0.0"/>
  </inertial>
  <visual>
    <origin xyz="-0.03 0.08 -0.038" rpy="0 0 0"/>
    <geometry>
      <mesh filename="file://$(find Assembly_scaled_description)/meshes/connector_v2_5.stl" scale="0.001 0.001 0.001"/>
    </geometry>
    <material name="silver"/>
  </visual>
  <collision>
    <origin xyz="-0.03 0.08 -0.038" rpy="0 0 0"/>
    <geometry>
      <mesh filename="file://$(find Assembly_scaled_description)/meshes/connector_v2_5.stl" scale="0.001 0.001 0.001"/>
    </geometry>
  </collision>
</link>

<link name="connector_v2_6">
  <inertial>
    <origin xyz="2.2351741846282636e-09 0.05000000000000001 2.9802319639893327e-10" rpy="0 0 0"/>
    <mass value="0.061653755826699685"/>
    <inertia ixx="5.2e-05" iyy="1e-06" izz="5.2e-05" ixy="0.0" iyz="0.0" ixz="0.0"/>
  </inertial>
  <visual>
    <origin xyz="-0.15 0.08 -0.038" rpy="0 0 0"/>
    <geometry>
      <mesh filename="file://$(find Assembly_scaled_description)/meshes/connector_v2_6.stl" scale="0.001 0.001 0.001"/>
    </geometry>
    <material name="silver"/>
  </visual>
  <collision>
    <origin xyz="-0.15 0.08 -0.038" rpy="0 0 0"/>
    <geometry>
      <mesh filename="file://$(find Assembly_scaled_description)/meshes/connector_v2_6.stl" scale="0.001 0.001 0.001"/>
    </geometry>
  </collision>
</link>

<link name="connector_v2_3">
  <inertial>
    <origin xyz="4.470348362317633e-10 0.04999999999999999 -8.940697002191023e-10" rpy="0 0 0"/>
    <mass value="0.061653755826699685"/>
    <inertia ixx="5.2e-05" iyy="1e-06" izz="5.2e-05" ixy="0.0" iyz="0.0" ixz="0.0"/>
  </inertial>
  <visual>
    <origin xyz="-0.03 0.08 0.042" rpy="0 0 0"/>
    <geometry>
      <mesh filename="file://$(find Assembly_scaled_description)/meshes/connector_v2_3.stl" scale="0.001 0.001 0.001"/>
    </geometry>
    <material name="silver"/>
  </visual>
  <collision>
    <origin xyz="-0.03 0.08 0.042" rpy="0 0 0"/>
    <geometry>
      <mesh filename="file://$(find Assembly_scaled_description)/meshes/connector_v2_3.stl" scale="0.001 0.001 0.001"/>
    </geometry>
  </collision>
</link>

<link name="connector_v2_1">
  <inertial>
    <origin xyz="4.470348362317633e-10 0.04999999999999999 -2.086162576020456e-09" rpy="0 0 0"/>
    <mass value="0.061653755826699685"/>
    <inertia ixx="5.2e-05" iyy="1e-06" izz="5.2e-05" ixy="0.0" iyz="-0.0" ixz="0.0"/>
  </inertial>
  <visual>
    <origin xyz="-0.03 0.08 0.122" rpy="0 0 0"/>
    <geometry>
      <mesh filename="file://$(find Assembly_scaled_description)/meshes/connector_v2_1.stl" scale="0.001 0.001 0.001"/>
    </geometry>
    <material name="silver"/>
  </visual>
  <collision>
    <origin xyz="-0.03 0.08 0.122" rpy="0 0 0"/>
    <geometry>
      <mesh filename="file://$(find Assembly_scaled_description)/meshes/connector_v2_1.stl" scale="0.001 0.001 0.001"/>
    </geometry>
  </collision>
</link>

<link name="connector_v2_2">
  <inertial>
    <origin xyz="2.2351741846282636e-09 0.04999999999999999 -2.086162576020456e-09" rpy="0 0 0"/>
    <mass value="0.061653755826699685"/>
    <inertia ixx="5.2e-05" iyy="1e-06" izz="5.2e-05" ixy="0.0" iyz="-0.0" ixz="0.0"/>
  </inertial>
  <visual>
    <origin xyz="-0.15 0.08 0.122" rpy="0 0 0"/>
    <geometry>
      <mesh filename="file://$(find Assembly_scaled_description)/meshes/connector_v2_2.stl" scale="0.001 0.001 0.001"/>
    </geometry>
    <material name="silver"/>
  </visual>
  <collision>
    <origin xyz="-0.15 0.08 0.122" rpy="0 0 0"/>
    <geometry>
      <mesh filename="file://$(find Assembly_scaled_description)/meshes/connector_v2_2.stl" scale="0.001 0.001 0.001"/>
    </geometry>
  </collision>
</link>

<link name="connector_v2_4">
  <inertial>
    <origin xyz="2.2351741846282636e-09 0.05000000000000001 -8.940697002191023e-10" rpy="0 0 0"/>
    <mass value="0.061653755826699685"/>
    <inertia ixx="5.2e-05" iyy="1e-06" izz="5.2e-05" ixy="0.0" iyz="0.0" ixz="0.0"/>
  </inertial>
  <visual>
    <origin xyz="-0.15 0.08 0.042" rpy="0 0 0"/>
    <geometry>
      <mesh filename="file://$(find Assembly_scaled_description)/meshes/connector_v2_4.stl" scale="0.001 0.001 0.001"/>
    </geometry>
    <material name="silver"/>
  </visual>
  <collision>
    <origin xyz="-0.15 0.08 0.042" rpy="0 0 0"/>
    <geometry>
      <mesh filename="file://$(find Assembly_scaled_description)/meshes/connector_v2_4.stl" scale="0.001 0.001 0.001"/>
    </geometry>
  </collision>
</link>

<link name="sampler_base_v3_1">
  <inertial>
    <origin xyz="1.341104505225843e-09 -0.037500000000000006 -8.940696863413145e-10" rpy="0 0 0"/>
    <mass value="3.31171875"/>
    <inertia ixx="0.003105" iyy="0.003105" izz="0.003105" ixy="0.0" iyz="0.0" ixz="0.0"/>
  </inertial>
  <visual>
    <origin xyz="-0.09 0.1 0.042" rpy="0 0 0"/>
    <geometry>
      <mesh filename="file://$(find Assembly_scaled_description)/meshes/sampler_base_v3_1.stl" scale="0.001 0.001 0.001"/>
    </geometry>
    <material name="silver"/>
  </visual>
  <collision>
    <origin xyz="-0.09 0.1 0.042" rpy="0 0 0"/>
    <geometry>
      <mesh filename="file://$(find Assembly_scaled_description)/meshes/sampler_base_v3_1.stl" scale="0.001 0.001 0.001"/>
    </geometry>
  </collision>
</link>

<link name="sampler_to_base_v3_1">
  <inertial>
    <origin xyz="1.341104505225843e-09 -0.01200000000000001 -8.940696516468449e-10" rpy="0 0 0"/>
    <mass value="0.3409206082193185"/>
    <inertia ixx="6.5e-05" iyy="9.8e-05" izz="6.5e-05" ixy="0.0" iyz="-0.0" ixz="0.0"/>
  </inertial>
  <visual>
    <origin xyz="-0.09 0.175 0.042" rpy="0 0 0"/>
    <geometry>
      <mesh filename="file://$(find Assembly_scaled_description)/meshes/sampler_to_base_v3_1.stl" scale="0.001 0.001 0.001"/>
    </geometry>
    <material name="silver"/>
  </visual>
  <collision>
    <origin xyz="-0.09 0.175 0.042" rpy="0 0 0"/>
    <geometry>
      <mesh filename="file://$(find Assembly_scaled_description)/meshes/sampler_to_base_v3_1.stl" scale="0.001 0.001 0.001"/>
    </geometry>
  </collision>
</link>

<link name="sampler_v4_1">
  <inertial>
    <origin xyz="1.3411058374934726e-09 -0.18823929339090956 0.051396299543399436" rpy="0 0 0"/>
    <mass value="0.8684306523577032"/>
    <inertia ixx="0.009358" iyy="0.002907" izz="0.006482" ixy="0.0" iyz="0.002317" ixz="0.0"/>
  </inertial>
  <visual>
    <origin xyz="-0.09 0.199 0.042" rpy="0 0 0"/>
    <geometry>
      <mesh filename="file://$(find Assembly_scaled_description)/meshes/sampler_v4_1.stl" scale="0.001 0.001 0.001"/>
    </geometry>
    <material name="silver"/>
  </visual>
  <collision>
    <origin xyz="-0.09 0.199 0.042" rpy="0 0 0"/>
    <geometry>
      <mesh filename="file://$(find Assembly_scaled_description)/meshes/sampler_v4_1.stl" scale="0.001 0.001 0.001"/>
    </geometry>
  </collision>
</link>

<link name="lidar_v3_1">
  <inertial>
    <origin xyz="1.341104505225843e-09 0.0225 -8.940696863413145e-10" rpy="0 0 0"/>
    <mass value="0.39015267359083405"/>
    <inertia ixx="0.0001" iyy="6.9e-05" izz="0.0001" ixy="0.0" iyz="0.0" ixz="0.0"/>
  </inertial>
  <visual>
    <origin xyz="-0.09 0.08 0.042" rpy="0 0 0"/>
    <geometry>
      <mesh filename="file://$(find Assembly_scaled_description)/meshes/lidar_v3_1.stl" scale="0.001 0.001 0.001"/>
    </geometry>
    <material name="silver"/>
  </visual>
  <collision>
    <origin xyz="-0.09 0.08 0.042" rpy="0 0 0"/>
    <geometry>
      <mesh filename="file://$(find Assembly_scaled_description)/meshes/lidar_v3_1.stl" scale="0.001 0.001 0.001"/>
    </geometry>
  </collision>
</link>

<joint name="Revolute 2" type="continuous">
  <origin xyz="0.18 0.01 -0.08" rpy="0 0 0"/>
  <parent link="base_link v5"/>
  <child link="wheel_f_v2_2"/>
  <axis xyz="1.0 0.0 0.0"/>
</joint>

<joint name="Revolute 3" type="continuous">
  <origin xyz="0.18 0.01 0.0" rpy="0 0 0"/>
  <parent link="base_link v5"/>
  <child link="wheel_f_v2_1"/>
  <axis xyz="1.0 0.0 0.0"/>
</joint>

<joint name="Revolute 4" type="continuous">
  <origin xyz="0.0 0.01 0.0" rpy="0 0 0"/>
  <parent link="base_link v5"/>
  <child link="wheel_f_v2_3"/>
  <axis xyz="-1.0 0.0 0.0"/>
</joint>

<joint name="Revolute 5" type="continuous">
  <origin xyz="0.0 0.01 -0.08" rpy="0 0 0"/>
  <parent link="base_link v5"/>
  <child link="wheel_f_v2_4"/>
  <axis xyz="-1.0 0.0 0.0"/>
</joint>

<joint name="Rigid 6" type="fixed">
  <origin xyz="0.03 -0.08 -0.122" rpy="0 0 0"/>
  <parent link="base_link v5"/>
  <child link="connector_v2_1"/>
</joint>

<joint name="Rigid 7" type="fixed">
  <origin xyz="0.15 -0.08 -0.122" rpy="0 0 0"/>
  <parent link="base_link v5"/>
  <child link="connector_v2_2"/>
</joint>

<joint name="Rigid 8" type="fixed">
  <origin xyz="0.03 -0.08 -0.042" rpy="0 0 0"/>
  <parent link="base_link v5"/>
  <child link="connector_v2_3"/>
</joint>

<joint name="Rigid 9" type="fixed">
  <origin xyz="0.15 -0.08 -0.042" rpy="0 0 0"/>
  <parent link="base_link v5"/>
  <child link="connector_v2_4"/>
</joint>

<joint name="Rigid 10" type="fixed">
  <origin xyz="0.03 -0.08 0.038" rpy="0 0 0"/>
  <parent link="base_link v5"/>
  <child link="connector_v2_5"/>
</joint>

<joint name="Rigid 11" type="fixed">
  <origin xyz="0.15 -0.08 0.038" rpy="0 0 0"/>
  <parent link="base_link v5"/>
  <child link="connector_v2_6"/>
</joint>
</robot>
