<?xml version="1.0" ?>

<robot name="diff_drive_robo" xmlns:xacro="http://www.ros.org/wiki/xacro">

  <xacro:arg name="sim_mode" default="true"/>
  <!-- <xacro:include filename="$(find frobo)/model/robod.gazebo"/> -->
  <xacro:include filename="$(find frobo)/model/ros2_control_real.xacro"/>

  <!-- <xacro:include filename="$(find frobo)/model/ros2_control.gazebo"/> -->

  <!-- Base link -->
  <link name="base_link"/>

  <!-- Base footprint link -->

  <joint name="footprint_joint" type="fixed">
    <parent link="base_link"/>
    <child link="base_footprint"/>
    <origin xyz= "0 0 0" rpy="0 0 0"/>
  </joint>
  
  <link name="base_footprint">
  </link>
  
  <!-- Chassis -->
  <joint name="dummy_joint" type="fixed">
    <parent link="base_link"/>
    <child link="chassis"/>
  </joint>

  <link name="chassis">
    <inertial>
      <origin xyz="0 0 -0.01" rpy="0 0 0" />
      <mass value="5.5241076800961295"/>
      <inertia ixx="0.018215" iyy="0.03263" izz="0.014783" ixy="0.0" iyz="0.0" ixz="0.0"/>
    </inertial>
    <visual>
      <origin xyz="0 0 0" rpy="0 0 0" />
      <geometry>
        <mesh filename="file://$(find frobo)/meshes/base_link.STL" />
      </geometry>
      <material name="">
        <color rgba="0.62745 0.62745 0.62745 1" />
      </material>
    </visual>
    <collision>
      <origin xyz="0 0 0" rpy="0 0 0" />
      <geometry>
        <mesh filename="file://$(find frobo)/meshes/base_link.STL" />
      </geometry>
    </collision>
  </link>

    <!-- Back right wheel -->

    <link name="back_right_wheel">
      <inertial>
        <origin xyz="0 0 0" rpy="0 0 0" />
        <mass value="0.8878140839044747"/>
        <inertia ixx="0.000555" iyy="0.000344" izz="0.000344" ixy="0.0" iyz="0.0" ixz="0.0"/> 
      </inertial>
      <visual>
        <origin xyz="0 0 0" rpy="0 0 0" />
        <geometry>
          <mesh filename="file://$(find frobo)/meshes/back_right_wheel.STL" />
        </geometry>
        <material name="">
          <color rgba="0.62745 0.62745 0.62745 1" />
        </material>
      </visual>
      <collision>
        <origin xyz="0 0 0" rpy="0 0 0" />
        <geometry>
          <mesh filename="file://$(find frobo)/meshes/back_right_wheel.STL" />
        </geometry>
      </collision>
    </link>
    
    <joint name="back_right_wheel_joint" type="continuous">
      <origin xyz="-0.038 -0.105 -0.01" rpy="1.5708 0 0" />
      <parent link="base_link" />
      <child link="back_right_wheel" />
      <axis xyz="0 0 -1" />
      <limit lower="-3.142" upper="3.142" effort="0" velocity="0" />
    </joint>
 
  <!-- Back Left Wheel -->

  <link name="back_left_wheel">
    <inertial>
      <origin xyz="0 0 0" rpy="0 0 0" />
      <mass value="0.8878140839044747"/>
      <inertia ixx="0.000555" iyy="0.000344" izz="0.000344" ixy="0.0" iyz="0.0" ixz="0.0"/>
    </inertial>
    <visual>
      <origin xyz="0 0 0" rpy="0 0 0" />
      <geometry>
        <mesh filename="file://$(find frobo)/meshes/back_left_wheel.STL" />
      </geometry>
      <material name="">
        <color rgba="0.62745 0.62745 0.62745 1" />
      </material>
    </visual>
    <collision>
      <origin xyz="0 0 0" rpy="0 0 0" />
      <geometry>
        <mesh filename="file://$(find frobo)/meshes/back_left_wheel.STL" />
      </geometry>
    </collision>
  </link>
  
  <joint name="back_left_wheel_joint" type="continuous">
    <origin xyz="-0.038 0.105 -0.01" rpy="1.5708 0 3.1416" />
    <parent link="base_link" />
    <child link="back_left_wheel" />
    <axis xyz="0 0 1" />
    <limit lower="-3.142" upper="3.142" effort="0" velocity="0" />
  </joint>
  
    <!-- front right wheel -->

    <link name="front_right_wheel">
      <inertial>
        <origin xyz="0 0 0" rpy="0 0 0" />
        <mass value="0.8878140839044747"/>
        <inertia ixx="0.000555" iyy="0.000344" izz="0.000344" ixy="0.0" iyz="0.0" ixz="0.0"/>
      </inertial>
      <visual>
        <origin xyz="0 0 0" rpy="0 0 0" />
        <geometry>
          <mesh filename="file://$(find frobo)/meshes/front_right_wheel.STL" />
        </geometry>
        <material name="">
          <color rgba="0.62745 0.62745 0.62745 1" />
        </material>
      </visual>
      <collision>
        <origin xyz="0 0 0" rpy="0 0 0" />
        <geometry>
          <mesh filename="file://$(find frobo)/meshes/front_right_wheel.STL" />
        </geometry>
      </collision>
    </link>
    
    <joint name="front_right_wheel_joint" type="continuous">
      <origin xyz="0.042 -0.105 -0.01" rpy="1.5708 0 0" />
      <parent link="base_link" />
      <child link="front_right_wheel" />
      <axis xyz="0 0 -1" />
      <limit lower="-3.142" upper="3.142" effort="0" velocity="0" />
    </joint>
    
  <!-- front left wheel -->
<link name="front_left_wheel">
    <inertial>
      <origin xyz="0 0 0" rpy="0 0 0" />
      <mass value="0.8878140839044747"/>
      <inertia ixx="0.000555" iyy="0.000344" izz="0.000344" ixy="0.0" iyz="0.0" ixz="0.0"/>
    </inertial>
    <visual>
      <origin xyz="0 0 0" rpy="0 0 0" />
      <geometry>
        <mesh filename="file://$(find frobo)/meshes/front_left_wheel.STL" />
      </geometry>
      <material name="">
        <color rgba="0.62745 0.62745 0.62745 1" />
      </material>
    </visual>
    <collision>
      <origin xyz="0 0 0" rpy="0 0 0" />
      <geometry>
        <mesh filename="file://$(find frobo)/meshes/front_left_wheel.STL" />
      </geometry>
    </collision>
  </link>
  
  <joint name="front_left_wheel_joint" type="continuous">
    <origin xyz="0.042 0.105 -0.01" rpy="1.5708 0 3.1416" />
    <parent link="base_link" />
    <child link="front_left_wheel" />
    <axis xyz="0 0 1" />
    <limit lower="-3.142" upper="3.142" effort="0" velocity="0" />
  </joint>
  
  <!-- connecting rods -->

  <link name="connecting_rods">
    <inertial>
      <origin xyz="0 0 0" rpy="0 0 0" />
      <mass value="0.047124" />
      <inertia ixx="3.9564E-05" ixy="0" ixz="0" iyy="3.9564E-05" iyz="0" izz="5.8905E-07" />
    </inertial>
    <visual>
      <origin xyz="0 0 0" rpy="0 0 0" />
      <geometry>
        <mesh filename="file://$(find frobo)/meshes/connecting_rods.STL" />
      </geometry>
      <material name="">
        <color rgba="0.62745 0.62745 0.62745 1" />
      </material>
    </visual>
    <collision>
      <origin xyz="0 0 0" rpy="0 0 0" />
      <geometry>
        <mesh filename="file://$(find frobo)/meshes/connecting_rods.STL" />
      </geometry>
    </collision>
  </link>
  
  <joint name="cr_low_joint" type="fixed">
    <origin xyz="0 0 0.03" rpy="0 0 0" />
    <parent link="base_link" />
    <child link="connecting_rods" />
    <axis xyz="0 0 0" />
  </joint>
  
  <!-- upper floor -->
  <link name="upper_floor">
    <inertial>
      
      <origin xyz="0 0 0.01" rpy="0 0 0" />
      <mass value="0.64039" />
      
      <inertia ixx="0.0015115" ixy="0" ixz="0" iyy="0.0020181" iyz="0" izz="0.0034869" />
    </inertial>
    <visual>
      <origin xyz="0 0 0" rpy="0 0 0" />
      <geometry>
        <mesh filename="file://$(find frobo)/meshes/upper_floor.STL" />
      </geometry>
      <material name="">
        <color rgba="0.62745 0.62745 0.62745 1" />
      </material>
    </visual>
    <collision>
      <origin xyz="0 0 0" rpy="0 0 0" />
      <geometry>
        <mesh filename="file://$(find frobo)/meshes/upper_floor.STL" />
      </geometry>
    </collision>
  </link>
  
  <joint name="cr_up_joint" type="fixed">
    <origin xyz="-0.0047489 0 0.05" rpy="0 0 0" />
    <parent link="connecting_rods" />
    <child link="upper_floor" />
    <axis xyz="0 0 0" />
  </joint>
  
  <!-- lidar -->
  <link name="lidar">
    <inertial>
     
      <origin xyz="0 0 0" rpy="0 0 0" />
      <mass value="0.39015267359083405"/>
      <inertia ixx="0.0001" iyy="6.9e-05" izz="0.0001" ixy="0.0" iyz="0.0" ixz="0.0"/>
    </inertial>
    <visual>
      <origin xyz="0 0 0" rpy="0 0 0" />
      <geometry>
        <mesh filename="file://$(find frobo)/meshes/lidar.STL" />
      </geometry>
      <material name="">
        <color rgba="0.62745 0.62745 0.62745 1" />
      </material>
    </visual>
    <collision>
      <origin xyz="0 0 0" rpy="0 0 0" />
      <geometry>
        <mesh filename="file://$(find frobo)/meshes/lidar.STL" />
      </geometry>
    </collision>
  </link>
  
  <joint name="lidar_joint" type="fixed">
    <origin xyz="0.0047489 0 -0.0225" rpy="0 0 0" />
    <parent link="upper_floor" />
    <child link="lidar" />
    <axis xyz="0 0 0" />
  </joint>
  
  <!-- sampler components -->

  <link name="sampler_box">
    <inertial>
      
      <origin xyz="0 0 0" rpy="0 0 0" />
      <mass value="0.31171875"/>
      <inertia ixx="0.003105" iyy="0.003105" izz="0.003105" ixy="0.0" iyz="0.0" ixz="0.0"/>
    </inertial>
    <visual>
      <origin xyz="0 0 0" rpy="0 0 0" />
      <geometry>
        <mesh filename="file://$(find frobo)/meshes/sampler_box.STL" />
      </geometry>
      <material name="">
        <color rgba="0.627450980392157 0.627450980392157 0.627450980392157 1" />
      </material>
    </visual>
    <collision>
      <origin xyz="0 0 0" rpy="0 0 0" />
      <geometry>
        <mesh filename="file://$(find frobo)/meshes/sampler_box.STL" />
      </geometry>
    </collision>
  </link>
  
  <joint name="up_floor_sampler_box" type="fixed">
    <origin xyz="0.0047489 0 0.095" rpy="0 0 0" />
    <parent link="upper_floor" />
    <child link="sampler_box" />
    <axis xyz="0 0 0" />
  </joint>
  
  <link name="sampler_cylinder">
    <inertial>
     
       <origin xyz="0 0 0" rpy="0 0 0" />
      <mass value="0.3409206082193185"/>
      <inertia ixx="6.5e-05" iyy="9.8e-05" izz="6.5e-05" ixy="0.0" iyz="0.0" ixz="0.0"/>
    </inertial>
    <visual>
      <origin xyz="0 0 0" rpy="0 0 0" />
      <geometry>
        <mesh filename="file://$(find frobo)/meshes/sampler_cylinder.STL" />
      </geometry>
      <material name="">
        <color rgba="0.62745 0.62745 0.62745 1" />
      </material>
    </visual>
    <collision>
      <origin xyz="0 0 0" rpy="0 0 0" />
      <geometry>
        <mesh filename="file://$(find frobo)/meshes/sampler_cylinder.STL" />
      </geometry>
    </collision>
  </link>
  
  <joint name="sampler_cyliner_joint" type="fixed">
    <origin xyz="0 0 0.012" rpy="0 0 0" />
    <parent link="sampler_box" />
    <child link="sampler_cylinder" />
    <axis xyz="0 0 0" />
  </joint>
  
  <link name="sampler_u">
    <inertial>
      <origin xyz="-0.00094401 -0.00043208 0.0044082" rpy="0 0 0" />
      <mass value="0.08684306523577032"/>
      <inertia ixx="0.009358" iyy="0.002907" izz="0.006482" ixy="0.0" iyz="0" ixz="0.0"/>
    </inertial>
    <visual>
      <origin xyz="0 0 0" rpy="0 0 0" />
      <geometry>
        <mesh filename="file://$(find frobo)/meshes/sampler_u.STL" />
      </geometry>
      <material name="">
        <color rgba="0.62745 0.62745 0.62745 1" />
      </material>
    </visual>
    <collision>
      <origin xyz="0 0 0" rpy="0 0 0" />
      <geometry>
        <mesh filename="file://$(find frobo)/meshes/sampler_u.STL" />
      </geometry>
    </collision>
  </link>
  
  <joint name="sampler_u_Joint" type="fixed">
    <origin xyz="0.052356 0.00043395 0.19583" rpy="0 0 0" />
    <parent link="sampler_cylinder" />
    <child link="sampler_u" />
    <axis xyz="0 0 0" />
  </joint>

</robot>